<?xml version="1.0" encoding="utf-8"?>
<!-- This URDF was automatically created by SolidWorks to URDF Exporter! Originally created by Stephen Brawner (brawner@gmail.com) 
     Commit Version: 1.6.0-1-g15f4949  Build Version: 1.6.7594.29634
     For more information, please see http://wiki.ros.org/sw_urdf_exporter -->
<robot
  name="mobilerobot">
  <link
    name="base_footprint_link">
    <inertial>
      <origin
        xyz="-0.0036066 5.5174E-07 0.096184"
        rpy="0 0 0" />
      <mass
        value="2.7711" />
      <inertia
        ixx="0.0077982"
        ixy="3.97E-09"
        ixz="-1.2658E-07"
        iyy="0.0082705"
        iyz="1.7767E-08"
        izz="0.013496" />
    </inertial>
    <visual>
      <origin
        xyz="0 0 0"
        rpy="0 0 0" />
      <geometry>
        <mesh
          filename="package://mobilerobot/meshes/base_footprint_link.STL" />
      </geometry>
      <material
        name="">
        <color
          rgba="0.79216 0.81961 0.93333 1" />
      </material>
    </visual>
    <collision>
      <origin
        xyz="0 0 0"
        rpy="0 0 0" />
      <geometry>
        <mesh
          filename="package://mobilerobot/meshes/base_footprint_link.STL" />
      </geometry>
    </collision>
  </link>
  <link
    name="base_link">
    <inertial>
      <origin
        xyz="-0.0036066 5.5174E-07 0.053637"
        rpy="0 0 0" />
      <mass
        value="2.7711" />
      <inertia
        ixx="0.0077982"
        ixy="3.97E-09"
        ixz="-1.2658E-07"
        iyy="0.0082705"
        iyz="1.7767E-08"
        izz="0.013496" />
    </inertial>
    <visual>
      <origin
        xyz="0 0 0"
        rpy="0 0 0" />
      <geometry>
        <mesh
          filename="package://mobilerobot/meshes/base_link.STL" />
      </geometry>
      <material
        name="">
        <color
          rgba="0.79216 0.81961 0.93333 1" />
      </material>
    </visual>
    <collision>
      <origin
        xyz="0 0 0"
        rpy="0 0 0" />
      <geometry>
        <mesh
          filename="package://mobilerobot/meshes/base_link.STL" />
      </geometry>
    </collision>
  </link>
  <joint
    name="base_link_joint"
    type="fixed">
    <origin
      xyz="0 0 0.0425463582228798"
      rpy="0 0 0" />
    <parent
      link="base_footprint_link" />
    <child
      link="base_link" />
    <axis
      xyz="0 0 0" />
  </joint>
  <link
    name="lw_link">
    <inertial>
      <origin
        xyz="-2.4925E-14 -0.024 3.0323E-15"
        rpy="0 0 0" />
      <mass
        value="0.6555" />
      <inertia
        ixx="0.00092301"
        ixy="-6.9389E-18"
        ixz="-6.861E-20"
        iyy="0.0016795"
        iyz="5.1584E-19"
        izz="0.00092301" />
    </inertial>
    <visual>
      <origin
        xyz="0 0 0"
        rpy="0 0 0" />
      <geometry>
        <mesh
          filename="package://mobilerobot/meshes/lw_link.STL" />
      </geometry>
      <material
        name="">
        <color
          rgba="0.79216 0.81961 0.93333 1" />
      </material>
    </visual>
    <collision>
      <origin
        xyz="0 0 0"
        rpy="0 0 0" />
      <geometry>
        <mesh
          filename="package://mobilerobot/meshes/lw_link.STL" />
      </geometry>
    </collision>
  </link>
  <joint
    name="lw_joint"
    type="continuous">
    <origin
      xyz="0.028202 0.175 0.033"
      rpy="0 0 0" />
    <parent
      link="base_link" />
    <child
      link="lw_link" />
    <axis
      xyz="0 1 0" />
  </joint>
  <link
    name="rw_link">
    <inertial>
      <origin
        xyz="4.996E-14 0.024 -1.2434E-14"
        rpy="0 0 0" />
      <mass
        value="0.6555" />
      <inertia
        ixx="0.00092301"
        ixy="-7.1557E-18"
        ixz="-6.861E-20"
        iyy="0.0016795"
        iyz="4.4977E-19"
        izz="0.00092301" />
    </inertial>
    <visual>
      <origin
        xyz="0 0 0"
        rpy="0 0 0" />
      <geometry>
        <mesh
          filename="package://mobilerobot/meshes/rw_link.STL" />
      </geometry>
      <material
        name="">
        <color
          rgba="0.79216 0.81961 0.93333 1" />
      </material>
    </visual>
    <collision>
      <origin
        xyz="0 0 0"
        rpy="0 0 0" />
      <geometry>
        <mesh
          filename="package://mobilerobot/meshes/rw_link.STL" />
      </geometry>
    </collision>
  </link>
  <joint
    name="rw_joint"
    type="continuous">
    <origin
      xyz="0.028202 -0.175 0.033"
      rpy="0 0 0" />
    <parent
      link="base_link" />
    <child
      link="rw_link" />
    <axis
      xyz="0 1 0" />
  </joint>
  <link
    name="caster_back_link">
    <inertial>
      <origin
        xyz="0.001251 0.0089126 -6.9389E-18"
        rpy="0 0 0" />
      <mass
        value="0.018145" />
      <inertia
        ixx="2.7833E-06"
        ixy="3.3411E-07"
        ixz="-2.6801E-22"
        iyy="5.1167E-06"
        iyz="-2.6817E-21"
        izz="2.7364E-06" />
    </inertial>
    <visual>
      <origin
        xyz="0 0 0"
        rpy="0 0 0" />
      <geometry>
        <mesh
          filename="package://mobilerobot/meshes/caster_back_link.STL" />
      </geometry>
      <material
        name="">
        <color
          rgba="0.79216 0.81961 0.93333 1" />
      </material>
    </visual>
    <collision>
      <origin
        xyz="0 0 0"
        rpy="0 0 0" />
      <geometry>
        <mesh
          filename="package://mobilerobot/meshes/caster_back_link.STL" />
      </geometry>
    </collision>
  </link>
  <joint
    name="caster_back_joint"
    type="continuous">
    <origin
      xyz="-0.15995 -0.0063367 -0.018546"
      rpy="0 0 0" />
    <parent
      link="base_link" />
    <child
      link="caster_back_link" />
    <axis
      xyz="-0.139 -0.99029 0" />
  </joint>
</robot>