<?xml version="1.0" encoding="utf-8"?>
<!-- This URDF was automatically created by SolidWorks to URDF Exporter! Originally created by Stephen Brawner (brawner@gmail.com) 
     Commit Version: 1.6.0-1-g15f4949  Build Version: 1.6.7594.29634
     For more information, please see http://wiki.ros.org/sw_urdf_exporter -->
<robot
  name="mobilerobot_description">
  <link
    name="base_footprint_link">
    <inertial>
      <origin
        xyz="-0.00360656709553187 5.51742622922902E-07 0.0961835709297454"
        rpy="0 0 0" />
      <mass
        value="2.7710684310164" />
      <inertia
        ixx="0.0077981909938028"
        ixy="3.97001787694196E-09"
        ixz="-1.26581058914571E-07"
        iyy="0.00827051967523543"
        iyz="1.7767419786386E-08"
        izz="0.0134964309780249" />
    </inertial>
    <visual>
      <origin
        xyz="0 0 0"
        rpy="0 0 0" />
      <geometry>
        <mesh
          filename="package://mobilerobot_description/meshes/base_footprint_link.STL" />
      </geometry>
      <material
        name="">
        <color
          rgba="0.792156862745098 0.819607843137255 0.933333333333333 1" />
      </material>
    </visual>
    <collision>
      <origin
        xyz="0 0 0"
        rpy="0 0 0" />
      <geometry>
        <mesh
          filename="package://mobilerobot_description/meshes/base_footprint_link.STL" />
      </geometry>
    </collision>
  </link>
  <link
    name="base_link">
    <inertial>
      <origin
        xyz="-0.00360656709553203 5.51742622978413E-07 0.0536372127068656"
        rpy="0 0 0" />
      <mass
        value="2.7710684310164" />
      <inertia
        ixx="0.0077981909938028"
        ixy="3.97001787694196E-09"
        ixz="-1.26581058914544E-07"
        iyy="0.00827051967523543"
        iyz="1.77674197863927E-08"
        izz="0.0134964309780249" />
    </inertial>
    <visual>
      <origin
        xyz="0 0 0"
        rpy="0 0 0" />
      <geometry>
        <mesh
          filename="package://mobilerobot_description/meshes/base_link.STL" />
      </geometry>
      <material
        name="">
        <color
          rgba="0.792156862745098 0.819607843137255 0.933333333333333 1" />
      </material>
    </visual>
    <collision>
      <origin
        xyz="0 0 0"
        rpy="0 0 0" />
      <geometry>
        <mesh
          filename="package://mobilerobot_description/meshes/base_link.STL" />
      </geometry>
    </collision>
  </link>
  <joint
    name="base_link_joint"
    type="fixed">
    <origin
      xyz="0 0 0.0425463582228798"
      rpy="0 0 0" />
    <parent
      link="base_footprint_link" />
    <child
      link="base_link" />
    <axis
      xyz="0 0 0" />
  </joint>
  <link
    name="lw_link">
    <inertial>
      <origin
        xyz="-2.4925E-14 -0.024 3.0323E-15"
        rpy="0 0 0" />
      <mass
        value="0.6555" />
      <inertia
        ixx="0.00092301"
        ixy="-7.1015E-18"
        ixz="-7.3692E-20"
        iyy="0.0016795"
        iyz="5.1161E-19"
        izz="0.00092301" />
    </inertial>
    <visual>
      <origin
        xyz="0 0 0"
        rpy="0 0 0" />
      <geometry>
        <mesh
          filename="package://mobilerobot_description/meshes/lw_link.STL" />
      </geometry>
      <material
        name="">
        <color
          rgba="0.79216 0.81961 0.93333 1" />
      </material>
    </visual>
    <collision>
      <origin
        xyz="0 0 0"
        rpy="0 0 0" />
      <geometry>
        <mesh
          filename="package://mobilerobot_description/meshes/lw_link.STL" />
      </geometry>
    </collision>
  </link>
  <joint
    name="lw_link_joint"
    type="continuous">
    <origin
      xyz="0.028202 0.175 0.033"
      rpy="0 0 0" />
    <parent
      link="base_link" />
    <child
      link="lw_link" />
    <axis
      xyz="0 1 0" />
  </joint>
  <link
    name="rw_link">
    <inertial>
      <origin
        xyz="4.996E-14 0.024 -1.2434E-14"
        rpy="0 0 0" />
      <mass
        value="0.6555" />
      <inertia
        ixx="0.00092301"
        ixy="-7.1557E-18"
        ixz="-7.7927E-20"
        iyy="0.0016795"
        iyz="4.4977E-19"
        izz="0.00092301" />
    </inertial>
    <visual>
      <origin
        xyz="0 0 0"
        rpy="0 0 0" />
      <geometry>
        <mesh
          filename="package://mobilerobot_description/meshes/rw_link.STL" />
      </geometry>
      <material
        name="">
        <color
          rgba="0.79216 0.81961 0.93333 1" />
      </material>
    </visual>
    <collision>
      <origin
        xyz="0 0 0"
        rpy="0 0 0" />
      <geometry>
        <mesh
          filename="package://mobilerobot_description/meshes/rw_link.STL" />
      </geometry>
    </collision>
  </link>
  <joint
    name="rw_link_joint"
    type="continuous">
    <origin
      xyz="0.028202 -0.175 0.033"
      rpy="0 0 0" />
    <parent
      link="base_link" />
    <child
      link="rw_link" />
    <axis
      xyz="0 1 0" />
  </joint>
  <link
    name="caster_back_link">
    <inertial>
      <origin
        xyz="0.001251 0.0089126 -6.9389E-18"
        rpy="0 0 0" />
      <mass
        value="0.018145" />
      <inertia
        ixx="2.7833E-06"
        ixy="3.3411E-07"
        ixz="-2.3823E-22"
        iyy="5.1167E-06"
        iyz="-2.6734E-21"
        izz="2.7364E-06" />
    </inertial>
    <visual>
      <origin
        xyz="0 0 0"
        rpy="0 0 0" />
      <geometry>
        <mesh
          filename="package://mobilerobot_description/meshes/caster_back_link.STL" />
      </geometry>
      <material
        name="">
        <color
          rgba="0.79216 0.81961 0.93333 1" />
      </material>
    </visual>
    <collision>
      <origin
        xyz="0 0 0"
        rpy="0 0 0" />
      <geometry>
        <mesh
          filename="package://mobilerobot_description/meshes/caster_back_link.STL" />
      </geometry>
    </collision>
  </link>
  <joint
    name="caster_link_joint"
    type="continuous">
    <origin
      xyz="-0.15995 -0.0063367 -0.018546"
      rpy="0 0 0" />
    <parent
      link="base_link" />
    <child
      link="caster_back_link" />
    <axis
      xyz="-0.139 -0.99029 0" />
  </joint>
  <link
    name="lidar_link">
    <inertial>
      <origin
        xyz="-1.6653E-16 0 -0.020971"
        rpy="0 0 0" />
      <mass
        value="0.17395" />
      <inertia
        ixx="8.3136E-05"
        ixy="6.7763E-21"
        ixz="8.6291E-20"
        iyy="8.3136E-05"
        iyz="4.251E-20"
        izz="0.00011843" />
    </inertial>
    <visual>
      <origin
        xyz="0 0 0"
        rpy="0 0 0" />
      <geometry>
        <mesh
          filename="package://mobilerobot_description/meshes/lidar_link.STL" />
      </geometry>
      <material
        name="">
        <color
          rgba="0.79216 0.81961 0.93333 1" />
      </material>
    </visual>
    <collision>
      <origin
        xyz="0 0 0"
        rpy="0 0 0" />
      <geometry>
        <mesh
          filename="package://mobilerobot_description/meshes/lidar_link.STL" />
      </geometry>
    </collision>
  </link>
  <joint
    name="lidar_link_joint"
    type="fixed">
    <origin
      xyz="0.1418 0 0.2168"
      rpy="0 0 0" />
    <parent
      link="base_link" />
    <child
      link="lidar_link" />
    <axis
      xyz="0 0 0" />
  </joint>
</robot>